package d

// Try calls f() and recovers from any panics caused by using d.Exp. The error generated by the call to d.Exp is returned.
func Try(f func()) (err error) {
	defer nomsRecover(&err)
	f()
	return
}

type nomsError struct {
	msg string
}

func (e nomsError) Error() string {
	return e.msg
}

func nomsRecover(errp *error) {
	if r := recover(); r != nil {
		if _, ok := r.(nomsError); !ok {
			panic(r)
		}
		*errp = r.(error)
	}
}
